Traceback (most recent call last):
  File "debug3(traceback).py", line 3, in <module>
    raise Exception('error error')
Exception: error error
